Workbook

Sheet Hoja2
B2: RESUMEN
B5: N° | C5: Parque | D5: Mes | E5: Año | F5: Fecha de Inicio | G5: Fecha de Término | H5: Dias Trabajados | I5: WTG | J5: Prom Diario | K5: Stand by
B6: 1 | C6: PUNTA LOMITAS | D6: Mayo | E6: 2026 | F6: =+'Parque 1 '!B3 -> 46181 | G6: =+'Parque 1 '!C3 -> 46189 | H6: =+'Parque 1 '!D3 -> 8 | I6: =+'Parque 1 '!E3 -> 58 | J6: =+'Parque 1 '!F3 -> 7.25 | K6: =+'Parque 1 '!G3 -> 1.16875
B7: 2
B8: 3
B9: 4
B10: 5
B11: 6
B12: 7
B13: 8
B14: 9
B15: 10
B16: 11
B17: 12
B18: 13
... B20: 15
B23: Total | K23: =SUBTOTAL(103,Tabla1[Stand by]) -> 1

Sheet Parque 1 
B1: Parque | C1: PUNTA LOMITAS
B2: Fecha de Inicio | C2: Fecha de Término | D2: Dias Trabajados | E2: WTG | F2: Prom Diario | G2: Stand by
B3: =+A5 -> 46181 | C3: =+A61 -> 46189 | D3: =+C3-B3 -> 8 | E3: =COUNT(C5:C62) -> 58 | F3: =+E3/D3 -> 7.25 | G3: =SUM(J5:J62) -> 1.16875
A4: Fecha | B4: Cant de WTG | C4: WTG | D4: Esfuerzos Inicio | E4: Traslado | F4: Parada de aero | G4: Esfuerzo final | H4: Inicio Aero | I4: Salida de parque | J4: Tiempo | K4: Observacion
A5: 46181 | B5: 8 | C5: 62 | D5: 0.33333333 | E5: =F5-D5 -> 0.125 | F5: 0.45833333 | G5: 0.48263889 | H5: =+G5 -> 0.48263889 | K5: Induccion
C6: 61 | D6: 0.48263889 | E6: =F6-D6 -> 0.0069444444 | F6: 0.48958333 | G6: 0.51180556 | H6: 0.51180556
C7: 60 | D7: 0.51180556 | E7: =F7-D7 -> 0.0048611111 | F7: 0.51666667 | G7: 0.53958333 | H7: 0.53958333
C8: 58 | D8: 0.53958333 | E8: =F8-D8 -> 0.0069444444 | F8: 0.54652778 | G8: 0.56875 | H8: 0.56875
C9: 57 | D9: 0.56875 | E9: =F9-D9 -> 0.0027777778 | F9: 0.57152778 | G9: 0.59444444 | H9: 0.59444444
C10: 56 | D10: 0.59444444 | E10: =F10-D10 -> 0.0055555556 | F10: 0.6 | G10: 0.62361111 | H10: 0.62361111
C11: 55 | D11: 0.62361111 | E11: =F11-D11 -> 0.0048611111 | F11: 0.62847222 | G11: 0.65416667 | H11: 0.65416667
C12: 54 | D12: 0.65416667 | E12: =F12-D12 -> 0.0027777778 | F12: 0.65694444 | G12: 0.68333333 | H12: 0.68333333 | I12: 0.70833333 | J12: =I12-H12 -> 0.025 | K12: Poca Luz
A13: 46182 | B13: 9 | C13: 59 | D13: 0.33333333 | E13: =F13-D13 -> 0.055555556 | F13: 0.38888889 | G13: 0.4125 | H13: 0.4125 | K13: Programacion
C14: 53 | D14: 0.4125 | E14: =F14-D14 -> 0.0076388889 | F14: 0.42013889 | G14: 0.44236111 | H14: 0.44236111
C15: 52 | D15: 0.44236111 | E15: =F15-D15 -> 0.0041666667 | F15: 0.44652778 | G15: 0.46805556 | H15: 0.46805556
C16: 51 | D16: 0.46805556 | E16: =F16-D16 -> 0.0034722222 | F16: 0.47152778 | G16: 0.49583333 | H16: 0.49583333
C17: 50 | D17: 0.49583333 | E17: =F17-D17 -> 0.0041666667 | F17: 0.5 | G17: 0.52291667 | H17: 0.52291667
C18: 47 | D18: 0.52291667 | E18: =F18-D18 -> 0.00625 | F18: 0.52916667 | G18: 0.55416667 | H18: 0.55416667
C19: 46 | D19: 0.55416667 | E19: =F19-D19 -> 0.0027777778 | F19: 0.55694444 | G19: 0.58263889 | H19: 0.58263889
C20: 45 | D20: 0.58263889 | E20: =F20-D20 -> 0.0034722222 | F20: 0.58611111 | G20: 0.61319444 | H20: 0.61319444
C21: 22 | D21: 0.61319444 | E21: =F21-D21 -> 0.0055555556 | F21: 0.61875 | G21: 0.64375 | H21: 0.64375 | I21: 0.70833333 | J21: =I21-H21 -> 0.064583333 | K21: Poca Luz
A22: 46184 | C22: 0 | D22: 0 | E22: 0 | F22: 0 | G22: 0 | H22: 0 | J22: 0.33333333 | K22: Dia Standby
A23: 46183 | C23: 3 | D23: 0.33333333 | E23: =F23-D23 -> 0.054861111 | F23: 0.38819444 | G23: 0.41041667 | H23: 0.41041667 | K23: Problemas con programacion
C24: 4 | D24: 0.41041667 | E24: =F24-D24 -> 0.0041666667 | F24: 0.41458333 | G24: 0.43888889 | H24: 0.43888889 | I24: 0.70833333 | J24: =I24-H24 -> 0.26944444 | K24: Viento Alto
A25: 46185 | C25: 44 | D25: 0.33333333 | E25: =F25-D25 -> 0.023611111 | F25: 0.35694444 | G25: 0.37986111 | H25: 0.37986111
C26: 43 | D26: 0.37986111 | E26: =F26-D26 -> 0.0020833333 | F26: 0.38194444 | G26: 0.40486111 | H26: 0.40486111
C27: 42 | D27: 0.40486111 | E27: =F27-D27 -> 0.0027777778 | F27: 0.40763889 | G27: 0.43611111 | H27: 0.43611111
C28: 41 | D28: 0.43611111 | E28: =F28-D28 -> 0.0041666667 | F28: 0.44027778 | G28: 0.46458333 | H28: 0.46458333
C29: 40 | D29: 0.46458333 | E29: =F29-D29 -> 0.0034722222 | F29: 0.46805556 | G29: 0.49097222 | H29: 0.49097222
C30: 39 | D30: 0.49097222 | E30: =F30-D30 -> 0.0034722222 | F30: 0.49444444 | G30: 0.51875 | H30: 0.51875
C31: 38 | D31: 0.51875 | E31: =F31-D31 -> 0.0027777778 | F31: 0.52152778 | G31: 0.57638889 | H31: 0.57638889
C32: 37 | D32: 0.57638889 | E32: =F32-D32 -> 0.0027777778 | F32: 0.57916667 | G32: 0.60138889 | H32: 0.60138889
C33: 36 | D33: 0.60138889 | E33: =F33-D33 -> 0.0027777778 | F33: 0.60416667 | G33: 0.62708333 | H33: 0.62708333
C34: 35 | D34: 0.62708333 | E34: =F34-D34 -> 0.0034722222 | F34: 0.63055556 | G34: 0.65555556 | H34: 0.65555556 | I34: 0.70833333 | J34: =I34-H34 -> 0.052777778 | K34: Poca Luz
A35: 46186 | C35: 34 | D35: 0.33333333 | E35: =F35-D35 -> 0.025 | F35: 0.35833333 | G35: 0.38055556 | H35: 0.38055556
C36: 33 | D36: 0.38055556 | E36: =F36-D36 -> 0.0034722222 | F36: 0.38402778 | G36: 0.40763889 | H36: 0.40763889
C37: 32 | D37: 0.40763889 | E37: =F37-D37 -> 0.0041666667 | F37: 0.41180556 | G37: 0.43333333 | H37: 0.43333333
C38: 31 | D38: 0.43333333 | E38: =F38-D38 -> 0.0027777778 | F38: 0.43611111 | G38: 0.45763889 | H38: 0.45763889
C39: 30 | D39: 0.45763889 | E39: =F39-D39 -> 0.0027777778 | F39: 0.46041667 | G39: 0.48194444 | H39: 0.48194444
C40: 29 | D40: 0.48194444 | E40: =F40-D40 -> 0.0027777778 | F40: 0.48472222 | G40: 0.50625 | H40: 0.50625
...
